Traceback (most recent call last):
  File "/Users/shubhangi/opt/anaconda3/lib/python3.8/site-packages/jupyter_cache/executors/utils.py", line 51, in single_nb_execution
    executenb(
  File "/Users/shubhangi/opt/anaconda3/lib/python3.8/site-packages/nbclient/client.py", line 1087, in execute
    return NotebookClient(nb=nb, resources=resources, km=km, **kwargs).execute()
  File "/Users/shubhangi/opt/anaconda3/lib/python3.8/site-packages/nbclient/util.py", line 74, in wrapped
    return just_run(coro(*args, **kwargs))
  File "/Users/shubhangi/opt/anaconda3/lib/python3.8/site-packages/nbclient/util.py", line 53, in just_run
    return loop.run_until_complete(coro)
  File "/Users/shubhangi/opt/anaconda3/lib/python3.8/asyncio/base_events.py", line 616, in run_until_complete
    return future.result()
  File "/Users/shubhangi/opt/anaconda3/lib/python3.8/site-packages/nbclient/client.py", line 540, in async_execute
    await self.async_execute_cell(
  File "/Users/shubhangi/opt/anaconda3/lib/python3.8/site-packages/nbclient/client.py", line 832, in async_execute_cell
    self._check_raise_for_error(cell, exec_reply)
  File "/Users/shubhangi/opt/anaconda3/lib/python3.8/site-packages/nbclient/client.py", line 740, in _check_raise_for_error
    raise CellExecutionError.from_cell_and_msg(cell, exec_reply['content'])
nbclient.exceptions.CellExecutionError: An error occurred while executing the following cell:
------------------
# enter your work here

n = 

V1 =  # m^3
V2 =  # m^3
p1 =  # bar
const = 
p2 = 

W = # work output in J
answer = W[0]/1000  # work output in kJ
print("The work done during process, W = %1.2f kJ " %answer)


import check_lab01 as p
p.check_p01(answer)
------------------

[0;36m  File [0;32m"<ipython-input-3-557c97ba10d0>"[0;36m, line [0;32m3[0m
[0;31m    n =[0m
[0m        ^[0m
[0;31mSyntaxError[0m[0;31m:[0m invalid syntax

SyntaxError: invalid syntax (<ipython-input-3-557c97ba10d0>, line 3)

